<?xml version="1.0"?>
<!--

  Copyright (c) 2011-2012, PAL Robotics, S.L.
  All rights reserved.

  This work is licensed under the Creative Commons Attribution-NonCommercial-NoDerivs 3.0 Unported License.
  To view a copy of this license, visit http://creativecommons.org/licenses/by-nc-nd/3.0/ or send a letter to
  Creative Commons, 444 Castro Street, Suite 900, Mountain View, California, 94041, USA.
-->
<robot xmlns:xacro="http://ros.org/wiki/xacro">

  <!--File includes-->
  <xacro:include filename="$(find reem_description)/urdf/deg_to_rad.xacro" />
  <xacro:include filename="$(find reem_description)/urdf/arm/wrist.urdf.xacro" />
  <xacro:include filename="$(find reem_description)/urdf/arm/arm.transmission.xacro" />

  <!--Constant parameters-->
  <xacro:property name="arm_friction"       value="1.0" />
  <xacro:property name="arm_damping"        value="1.0" />
  <xacro:property name="arm_max_vel"        value="1.0" />
  <xacro:property name="arm_eps"            value="0.02" />

  <!-- TODO: Update dynamic models -->

  <xacro:macro name="reem_arm" params="name parent side reflect">

    <!--************************-->
    <!--        SHOULDER        -->
    <!--************************-->
    <link name="${name}_${side}_1_link">
      <inertial>
        <origin xyz="0.0006 -0.0005 ${reflect*0.20739}" rpy="0 0 0"/>
        <mass value="2.148" />
        <inertia ixx="0"  ixy="0"  ixz="0" iyy="0" iyz="0" izz="0" />
<!--         NOTE: Assuming cylinder centered at CoM with r=0.05, h=0.05 with axis parallel to x coordinate -->
<!--         <inertia ixx="0.0026850"  ixy="0"  ixz="0" iyy="0.0017900" iyz="0" izz="0.0017900" /> -->
      </inertial>
      <visual>
        <origin xyz="0 0 0" rpy="0 0 0" />
        <geometry>
          <mesh filename="package://reem_description/meshes/arm/arm_1.dae" scale="1 1 ${-1*reflect}"/>
        </geometry>
        <material name="DarkGrey" />
      </visual>
      <collision>
       <origin xyz="0 0 0" rpy="0 0 0" />
        <geometry>
          <mesh filename="package://reem_description/meshes/arm/arm_1_collision.stl" scale="1 1 ${-1*reflect}"/>
        </geometry>
      </collision>
    </link>

    <joint name="${name}_${side}_1_joint" type="revolute">
      <parent link="${parent}" />
      <child link="${name}_${side}_1_link" />
      <origin xyz="-0.015 -0.273 0" rpy="${(-165.0*reflect) * deg_to_rad} 0 0" />
      <axis xyz="0 0 1" />
      <limit lower="${-45.0 * deg_to_rad}" upper="${180.0 * deg_to_rad}" effort="39" velocity="${arm_max_vel}" />
      <dynamics friction="${arm_friction}" damping="${arm_damping}"/>

      <safety_controller k_position="20"
                         k_velocity="20"
                         soft_lower_limit="${-45.0 * deg_to_rad  + arm_eps}"
                         soft_upper_limit="${ 180.0 * deg_to_rad - arm_eps}" />
    </joint>

   <link name="${name}_${side}_2_link">
      <inertial>
        <origin xyz="0.0183 -0.09275 ${reflect*0.00478}" rpy="0 0 0"/>
        <mass value="1.610" />
        <inertia ixx="0"  ixy="0"  ixz="0" iyy="0" iyz="0" izz="0" />
        <!-- NOTE: Assuming cylinder centered at CoM with r=0.05, h=0.05 with axis parallel to y coordinate -->
<!--         <inertia ixx="0.0013417"  ixy="0"  ixz="0" iyy="0.0020125" iyz="0" izz="0.0013417" /> -->
      </inertial>
      <visual>
        <origin xyz="0 0 0" rpy="0 0 0" />
        <geometry>
          <mesh filename="package://reem_description/meshes/arm/arm_2.dae" scale="1 1 ${-1*reflect}"/>
        </geometry>
        <material name="DarkGrey" />
      </visual>
      <collision>
        <origin xyz="0 0 0" rpy="0 0 0" />
        <geometry>
          <mesh filename="package://reem_description/meshes/arm/arm_2_collision.stl" scale="1 1 ${-1*reflect}"/>
        </geometry>
      </collision>
    </link>

    <joint name="${name}_${side}_2_joint" type="revolute">
      <parent link="${name}_${side}_1_link" />
      <child link="${name}_${side}_2_link" />
      <origin xyz="0 0 ${0.2385 * reflect}" rpy="${-90.0 * reflect * deg_to_rad} ${-75.0 * reflect * deg_to_rad} ${90.0 * deg_to_rad}" />
      <axis xyz="0 0 1" />
      <limit lower="${-15.0 * deg_to_rad}" upper="${120.0 * deg_to_rad}" effort="21.7" velocity="${arm_max_vel}" />
      <dynamics friction="${arm_friction}" damping="${arm_damping}"/>

      <safety_controller k_position="20"
                         k_velocity="20"
                         soft_lower_limit="${-15.0 * deg_to_rad  + arm_eps}"
                         soft_upper_limit="${ 120.0 * deg_to_rad - arm_eps}" />
    </joint>

    <link name="${name}_${side}_3_link">
      <inertial>
        <origin xyz="0.00045 -0.01547 ${reflect * 0.07654}" rpy="0 0 0"/>
        <mass value="1.656" />
        <inertia ixx="0"  ixy="0"  ixz="0" iyy="0" iyz="0" izz="0" />
        <!-- NOTE: Assuming cylinder centered at CoM with r=0.05, h=0.05 with axis parallel to x coordinate -->
<!--         <inertia ixx="0.0020700"  ixy="0"  ixz="0" iyy="0.0013800" iyz="0" izz="0.0013800" /> -->
      </inertial>
      <visual>
        <origin xyz="0 0 0" rpy="0 0 0" />
        <geometry>
          <mesh filename="package://reem_description/meshes/arm/arm_3.dae" scale="1 1 ${-1*reflect}"/>
        </geometry>
        <material name="DarkGrey" />
      </visual>
      <collision>
        <origin xyz="0 0 0" rpy="0 0 0" />
        <geometry>
          <mesh filename="package://reem_description/meshes/arm/arm_3_collision.stl" scale="1 1 ${-1*reflect}"/>
        </geometry>
      </collision>
    </link>

    <joint name="${name}_${side}_3_joint" type="revolute">
      <parent link="${name}_${side}_2_link" />
      <child link="${name}_${side}_3_link" />
      <origin xyz="0.02 -0.142 0" rpy="${90.0 * reflect * deg_to_rad} 0 0" />
      <axis xyz="0 0 1" />
      <limit lower="${-135.0 * deg_to_rad}" upper="${157.5 * deg_to_rad}" effort="17.4" velocity="${arm_max_vel}" />
      <dynamics friction="${arm_friction}" damping="${arm_damping}"/>

      <safety_controller k_position="20"
                         k_velocity="20"
                         soft_lower_limit="${-135.0 * deg_to_rad + arm_eps}"
                         soft_upper_limit="${ 157.5 * deg_to_rad - arm_eps}" />
    </joint>

    <!--************************-->
    <!--        ELBOW           -->
    <!--************************-->
    <link name="${name}_${side}_4_link">
      <inertial>
        <origin xyz="-0.06424 0.01712 ${-reflect * 0.00666}" rpy="0 0 0"/>
        <mass value="1.013" />
        <inertia ixx="0"  ixy="0"  ixz="0" iyy="0" iyz="0" izz="0" />
        <!-- NOTE: Assuming cylinder centered at CoM with r=0.05, h=0.05 with axis parallel to x coordinate -->
<!--         <inertia ixx="0.0012663"  ixy="0"  ixz="0" iyy="0.00084417" iyz="0" izz="0.00084417" /> -->
      </inertial>
      <visual>
        <origin xyz="0 0 0" rpy="0 0 0" />
        <geometry>
          <mesh filename="package://reem_description/meshes/arm/arm_4.dae" scale="1 1 ${-1*reflect}"/>
        </geometry>
        <material name="DarkGrey" />
      </visual>
      <collision>
        <origin xyz="0 0 0" rpy="0 0 0" />
        <geometry>
          <mesh filename="package://reem_description/meshes/arm/arm_4_collision.stl" scale="1 1 ${-1*reflect}"/>
        </geometry>
      </collision>
    </link>

    <joint name="${name}_${side}_4_joint" type="revolute">
      <parent link="${name}_${side}_3_link" />
      <child link="${name}_${side}_4_link" />
      <origin xyz="0 -0.02 ${0.088 * reflect}" rpy="0 ${90.0 * reflect * deg_to_rad} 0" />
      <axis xyz="0 0 1" />
      <limit lower="0" upper="${130.0 * deg_to_rad}" effort="17.4" velocity="${arm_max_vel}" />
      <dynamics friction="${arm_friction}" damping="${arm_damping}"/>

      <safety_controller k_position="20"
                         k_velocity="20"
                         soft_lower_limit="${0.0 * deg_to_rad}"
                         soft_upper_limit="${ 130.0 * deg_to_rad - arm_eps}" />
    </joint>

   <gazebo reference="${name}_${side}_1_link">
     <mu1>0.9</mu1>
     <mu2>0.9</mu2>
   </gazebo>
   <gazebo reference="${name}_${side}_2_link">
     <mu1>0.9</mu1>
     <mu2>0.9</mu2>
   </gazebo>
   <gazebo reference="${name}_${side}_3_link">
     <mu1>0.9</mu1>
     <mu2>0.9</mu2>
   </gazebo>
   <gazebo reference="${name}_${side}_4_link">
     <mu1>0.9</mu1>
     <mu2>0.9</mu2>
   </gazebo>

   <gazebo reference="${name}_${side}_1_joint">
      <cfmDamping>1</cfmDamping>
   </gazebo>
   <gazebo reference="${name}_${side}_2_joint">
      <cfmDamping>1</cfmDamping>
   </gazebo>
   <gazebo reference="${name}_${side}_3_joint">
      <cfmDamping>1</cfmDamping>
   </gazebo>
   <gazebo reference="${name}_${side}_4_joint">
      <cfmDamping>1</cfmDamping>
   </gazebo>


    <!--************************-->
    <!--        WRIST           -->
    <!--************************-->
    <xacro:reem_wrist name="arm" parent="${name}_${side}_4_link" side="${side}" reflect="${reflect}"  />

    <!--***********************-->
    <!--        TOOL           -->
    <!--***********************-->
    <link name="${name}_${side}_tool_link">
      <inertial>
        <mass value="0.1" />
        <inertia ixx="0.0" ixy="0.0" ixz="0.0" iyy="0.0" iyz="0.0" izz="0.0" />
      </inertial>
      <visual>
        <origin xyz="0.001 0 0" rpy="0 ${90.0 * deg_to_rad} 0" />
        <geometry>
          <cylinder radius="0.005" length="0.005"/>
        </geometry>
        <material name="LightGrey" />
      </visual>
      <collision>
        <origin xyz="0.001 0 0" rpy="0 ${90.0 * deg_to_rad} 0" />
        <geometry>
          <cylinder radius="0.005" length="0.005"/>
        </geometry>
      </collision>
    </link>

    <joint name="${name}_${side}_tool_joint" type="fixed">
      <parent link="${name}_${side}_7_link" />
      <child link="${name}_${side}_tool_link" />
      <origin xyz="0 0 ${reflect * 0.046}" rpy="${90.0 * deg_to_rad} ${-90.0 * reflect * deg_to_rad} 0" />
    </joint>


    <!-- extensions -->
    <xacro:reem_shoulder_transmission name="${name}" side="${side}" number="1"
                                      act_reduction_1="1.0" act_reduction_2="-1.0"
                                      jnt_reduction_1="1.0" jnt_reduction_2="-1.0"/>
    
    <xacro:reem_arm_simple_transmission name="${name}" side="${side}" number="2" reduction="1.0" />
    <xacro:reem_arm_simple_transmission name="${name}" side="${side}" number="3" reduction="1.0" />
    <xacro:reem_arm_simple_transmission name="${name}" side="${side}" number="4" reduction="1.0" />

  </xacro:macro>

</robot>
