<?xml version="1.0"?>
<!--

  Copyright (c) 2011-2012, PAL Robotics, S.L.
  All rights reserved.

  This work is licensed under the Creative Commons Attribution-NonCommercial-NoDerivs 3.0 Unported License.
  To view a copy of this license, visit http://creativecommons.org/licenses/by-nc-nd/3.0/ or send a letter to
  Creative Commons, 444 Castro Street, Suite 900, Mountain View, California, 94041, USA.
-->
<robot xmlns:xacro="http://ros.org/wiki/xacro">

  <!--File includes-->
  <xacro:include filename="$(find reem_description)/urdf/deg_to_rad.xacro" />
  <xacro:include filename="$(find reem_description)/urdf/arm/wrist.transmission.xacro" />

  <!--Constant parameters-->
  <xacro:property name="wrist_friction"     value="1.0" />
  <xacro:property name="wrist_max_vel"      value="1.0" />
  <xacro:property name="wrist_eps"          value="0.02" />

  <!-- TODO: Update dynamic models -->

  <xacro:macro name="reem_wrist" params="name parent side reflect">

    <!--************************-->
    <!--        WRIST           -->
    <!--************************-->
    <link name="${name}_${side}_5_link">
      <inertial>
        <origin xyz="-0.00045 -0.00009 ${reflect * 0.08726}" rpy="0 0 0"/>
        <mass value="1.858" />
        <inertia ixx="0"  ixy="0"  ixz="0" iyy="0" iyz="0" izz="0" />
        <!-- NOTE: Assuming cylinder centered at CoM with r=0.05, h=0.1 with axis parallel to z coordinate -->
<!--         <inertia ixx="0.0027096"  ixy="0"  ixz="0" iyy="0.0027096" iyz="0" izz="0.0023225" /> -->
      </inertial>
      <visual>
        <origin xyz="0 0 0" rpy="0 0 0" />
        <geometry>
          <mesh filename="package://reem_description/meshes/arm/arm_5.dae" scale="1 1 ${-1*reflect}"/>
        </geometry>
        <material name="LightGrey" />
      </visual>
      <collision>
        <origin xyz="0 0 0" rpy="0 0 0" />
        <geometry>
          <mesh filename="package://reem_description/meshes/arm/arm_5_collision.stl" scale="1 1 ${-1*reflect}"/>
        </geometry>
      </collision>
    </link>

    <joint name="${name}_${side}_5_joint" type="revolute">
      <parent link="${parent}" />
      <child link="${name}_${side}_5_link" />
      <origin xyz="-0.088 0.02 0" rpy="0 ${-90.0 * reflect * deg_to_rad} 0" />
      <axis xyz="0 0 1" />
      <limit lower="${-120.0 * deg_to_rad}" upper="${120.0 * deg_to_rad}" effort="16" velocity="${wrist_max_vel}" /> <!--TODO: Check effort value!-->
      <dynamics friction="${wrist_friction}" damping="0.5"/>

      <safety_controller k_position="20"
                         k_velocity="20"
                         soft_lower_limit="${-120.0 * deg_to_rad + wrist_eps}"
                         soft_upper_limit="${ 120.0 * deg_to_rad - wrist_eps}" />
    </joint>

    <link name="${name}_${side}_6_link">
      <inertial>
        <origin xyz="-0.0002 -0.01155 ${reflect * 0.00002}" rpy="0 0 0"/>
        <mass value="0.255" />
        <inertia ixx="0"  ixy="0"  ixz="0" iyy="0" iyz="0" izz="0" />
        <!-- NOTE: Assuming cylinder centered at CoM with r=0.02, h=0.08 with axis parallel to z coordinate -->
<!--         <inertia ixx="0.0001615"  ixy="0"  ixz="0" iyy="0.0001615" iyz="0" izz="0.000051" /> -->
      </inertial>
      <visual>
        <origin xyz="0 0 0" rpy="0 0 0" />
        <geometry>
          <mesh filename="package://reem_description/meshes/arm/arm_6.dae" scale="1 1 ${-1*reflect}"/>
        </geometry>
        <material name="LightGrey" />
      </visual>
      <collision>
        <origin xyz="0 0 0" rpy="0 0 0" />
        <geometry>
          <cylinder radius="0.04" length="0.0385"/>
        </geometry>
      </collision>
    </link>

    <joint name="${name}_${side}_6_joint" type="revolute">
      <parent link="${name}_${side}_5_link" />
      <child link="${name}_${side}_6_link" />
      <origin xyz="0 0 ${0.15 * reflect}" rpy="${-90.0 * reflect * deg_to_rad} 0 0" />
      <axis xyz="0 0 1" />
      <limit lower="${-90.0 * deg_to_rad}" upper="${90.0 * deg_to_rad}" effort="12" velocity="${wrist_max_vel}" />
      <dynamics friction="${wrist_friction}" damping="0.1"/>

      <safety_controller k_position="20"
                         k_velocity="20"
                         soft_lower_limit="${-90.0 * deg_to_rad + wrist_eps}"
                         soft_upper_limit="${ 90.0 * deg_to_rad - wrist_eps}" />
    </joint>

    <link name="${name}_${side}_7_link">
      <inertial>
        <!--TODO: Verify these inertial parameters-->
        <origin xyz="0 0 ${reflect * 0.109404509 / 2}" rpy="0 0 0"/>
        <mass value="0.152461831" />
        <inertia ixx="0"  ixy="0"  ixz="0" iyy="0" iyz="0" izz="0" />
        <!-- NOTE: Assuming point mass -->
<!--         <inertia ixx="0"  ixy="0"  ixz="0" iyy="0" iyz="0" izz="0" /> -->
      </inertial>
      <visual>
        <origin xyz="0 0 ${0.046 * reflect}" rpy="0 0 0" />
        <geometry>
          <cylinder radius="0.02" length="0.005"/>
        </geometry>
        <material name="DarkGrey" />
      </visual>
      <collision>
        <origin xyz="0 0 ${0.046 * 0.75 * reflect}" rpy="0 0 0" />
        <geometry>
          <cylinder radius="0.02" length="0.023"/>
        </geometry>
      </collision>
    </link>

    <joint name="${name}_${side}_7_joint" type="revolute">
      <parent link="${name}_${side}_6_link" />
      <child link="${name}_${side}_7_link" />
      <origin xyz="0 0 0" rpy="${90.0 * reflect * deg_to_rad} 0 0" />
      <axis xyz="0 0 1" />
      <limit lower="${-120.0 * deg_to_rad}" upper="${120.0 * deg_to_rad}" effort="12" velocity="${wrist_max_vel}" />
      <dynamics friction="${wrist_friction}" damping="0.1"/>

      <safety_controller k_position="20"
                         k_velocity="20"
                         soft_lower_limit="${-120.0 * deg_to_rad + wrist_eps}"
                         soft_upper_limit="${ 120.0 * deg_to_rad - wrist_eps}" />
    </joint>

    <gazebo reference="${name}_${side}_5_link">
      <mu1>0.9</mu1>
      <mu2>0.9</mu2>
    </gazebo>
    <gazebo reference="${name}_${side}_6_link">
      <mu1>0.9</mu1>
      <mu2>0.9</mu2>
    </gazebo>
    <gazebo reference="${name}_${side}_7_link">
      <mu1>0.9</mu1>
      <mu2>0.9</mu2>
    </gazebo>

    <gazebo reference="${name}_${side}_5_joint">
        <cfmDamping>1</cfmDamping>
    </gazebo>
    <gazebo reference="${name}_${side}_6_joint">
        <cfmDamping>1</cfmDamping>
    </gazebo>
    <gazebo reference="${name}_${side}_7_joint">
        <cfmDamping>1</cfmDamping>
    </gazebo>

    <!-- extensions -->
    <xacro:reem_wrist_simple_transmission name="${name}" side="${side}" number="5" reduction="1.0" />
    <xacro:reem_wrist_differential_transmission name="${name}" side="${side}" number_1="6" number_2="7"
                                                act_reduction_1="-1.0" act_reduction_2="1.0"
                                                jnt_reduction_1="-1.0" jnt_reduction_2="${-reflect}" />

  </xacro:macro>

</robot>
